<?xml version="1.0"?>
<robot name="my_bot">

    <material name="yellow_light">
        <color rgba="1.0 1.0 0.0 0.7"/>
    </material>

    <material name ='wooden'>
        <color rgba='0.76 0.60 0.024 1'/>
    </material>

    <material name ='black'>
        <color rgba='0.0 0.0 0.0 1'/>
    </material>

    <link name="base_link">
    </link>

    <link name="base_footprint">
    </link>
    
    <joint name="footprint_joint" type="fixed">
        <parent link="base_link"/>
        <child link="base_footprint"/>
        <origin xyz="0 0 0" rpy="0 0 0"/>
    </joint>

    <!-- B O D Y -->
    <link name="chassis">
        <visual>
            <geometry>
                <box size="0.3 0.54 0.15"/>
            </geometry>
            <material name="wooden"/>
        </visual>

        <collision>
            <geometry>
                <box size="0.3 0.54 0.15"/>
            </geometry>
        </collision>

        <inertial>
            <mass value="0.1"/>
            <origin rpy="0 0 0" xyz="0 0 0"/>
            <inertia ixx=" 0.0026175000000000005" ixy="0" ixz="0" iyy="0.0009375" iyz="0" izz="0.004860000000000001"/>
        </inertial>

    </link>

    <joint name="base_link_joint" type="fixed">
        <origin rpy="0 0 1.57" xyz="0 0 0" />
        <parent link="base_link" />
        <child link="chassis" />
    </joint>

    <!-- Wheel Left -->
    <link name="left_wheel">
        <visual>
            <origin rpy="0 1.5707 0" xyz="0 0 0"/>
            <geometry>
                <cylinder length="0.06" radius="0.09"/>
            </geometry>
            <material name="yellow_light"/>
        </visual>

        <collision>
            <origin rpy="0 1.5707 0" xyz="0 0 0"/>
            <geometry>
                <cylinder length="0.06" radius="0.09"/>
            </geometry>
        </collision>

        <inertial>
            <origin rpy="0 1.5707 0" xyz="0 0 0"/>
            <mass value="0.1"/>
            <inertia ixx="0.00023250000000000004" ixy="0" ixz="0" iyy="0.00023250000000000004" iyz="0" izz="0.000405"/>
        </inertial>
    </link>
    
    <gazebo reference="left_wheel">
        <kp>100000000000000000000.0</kp>
        <kd>100000000000000000000.0</kd>
        <mu1>10</mu1>
        <mu2>10</mu2>
        <material>Gazebo/Black</material>
    </gazebo>

    <joint name="joint_left_wheel" type="continuous">
        <origin rpy="0 0 0" xyz="0.18 0 -0.025"/>
        <child link="left_wheel"/>
        <parent link="chassis"/>
        <axis rpy="0 0 0" xyz="1 0 0"/>
        <limit effort="10000" velocity="1000"/>
        <joint_properties damping="1.0" friction="1.0"/>
    </joint>

    <!-- Wheel Right -->
    <link name="right_wheel">
        <visual>
            <origin rpy="0 1.5707 0" xyz="0 0 0"/>
            <geometry>
                <cylinder length="0.06" radius="0.09"/>
            </geometry>
            <material name="yellow_light"/>
        </visual>

        <collision>
            <origin rpy="0 1.5707 0" xyz="0 0 0"/>
            <geometry>
                <cylinder length="0.06" radius="0.09"/>
            </geometry>
        </collision>

        <inertial>
            <origin rpy="0 1.5707 0" xyz="0 0 0"/>
            <mass value="0.1"/>
            <inertia ixx="0.00023250000000000004" ixy="0" ixz="0" iyy="0.00023250000000000004" iyz="0" izz="0.000405"/>
        </inertial>
    </link>

    <gazebo reference="right_wheel">
        <kp>100000000000000000000.0</kp>
        <kd>100000000000000000000.0</kd>
        <mu1>10</mu1>
        <mu2>10</mu2>
        <material>Gazebo/Black</material>
    </gazebo>

    <joint name="joint_right_wheel" type="continuous">
        <origin rpy="0 0 0" xyz="-0.18 0 -0.025"/>
        <child link="right_wheel"/>
        <parent link="chassis"/>
        <axis rpy="0 0 0" xyz="1 0 0"/>
        <limit effort="10000" velocity="1000"/>
        <joint_properties damping="1.0" friction="1.0"/>
    </joint>

    <!-- Caster Wheel Front -->
    <link name="front_yaw_link">
        <visual>
            <origin rpy="0 1.5707 1.5707" xyz="0 0 0"/>
            <geometry>
              <cylinder length="0.005" radius="0.04"/>
            </geometry>
            <material name="wooden"/>
        </visual>

        <collision>
            <origin rpy="0 1.5707 1.5707" xyz="0 0 0"/>
            <geometry>
                <cylinder length="0.005" radius="0.04"/>
            </geometry>
        </collision>

        <inertial>
            <origin rpy="0 1.5707 1.5707" xyz="0 0 0"/>
            <mass value="0.001"/>
            <inertia ixx="4.020833333333333e-07" ixy="0" ixz="0" iyy="4.020833333333333e-07" iyz="0" izz="8.000000000000001e-07"/>
        </inertial>
    </link>

    <joint name="front_yaw_joint" type="continuous">
        <origin rpy="0 0 0" xyz="0 -0.15 -0.075"/>
        <parent link="chassis" />
        <child link="front_yaw_link" />
        <axis xyz="0 0 1" />
        <limit effort="1000.0" velocity="100.0" />
        <dynamics damping="0.0" friction="0.1"/>
    </joint>

    <gazebo reference="front_yaw_link">
        <material>Gazebo/Purple</material>
    </gazebo>

    <link name="front_roll_link">
        <visual>
            <origin rpy="0 1.5707 1.5707" xyz="0 0 0"/>
            <geometry>
                <cylinder length="0.005" radius="0.04"/>
            </geometry>
            <material name="wooden"/>
        </visual>

        <collision>
            <origin rpy="0 1.5707 1.5707" xyz="0 0 0"/>
            <geometry>
                <cylinder length="0.005" radius="0.04"/>
            </geometry>
        </collision>

        <inertial>
            <origin rpy="0 1.5707 1.5707" xyz="0 0 0"/>
            <mass value="0.001"/>
            <inertia ixx="4.020833333333333e-07" ixy="0" ixz="0" iyy="4.020833333333333e-07" iyz="0" izz="8.000000000000001e-07"/>
        </inertial>
    </link>

    <joint name="front_roll_joint" type="continuous">
        <origin rpy="0 0 0" xyz="0 0 0" />
        <parent link="front_yaw_link" />
        <child link="front_roll_link" />
        <axis xyz="1 0 0" />
        <limit effort="1000.0" velocity="100.0" />
        <dynamics damping="0.0" friction="0.1"/>
    </joint>
        
    <gazebo reference="front_roll_link">
        <material>Gazebo/Purple</material>
    </gazebo>

    <link name="front_pitch_link">
        <visual>
            <origin rpy="0 1.5707 1.5707" xyz="0 0 0"/>
            <geometry>
                <sphere radius="0.04"/>
            </geometry>
            <material name="wooden"/>
        </visual>

        <collision>
            <origin rpy="0 1.5707 1.5707" xyz="0 0 0"/>
            <geometry>
                <sphere radius="0.04"/>
            </geometry>
        </collision>

        <inertial>
            <origin rpy="0 1.5707 1.5707" xyz="0 0 0"/>
            <mass value="0.001"/>
            <inertia ixx="6.4e-07" ixy="0" ixz="0" iyy="6.4e-07" iyz="0" izz="6.4e-07"/>
        </inertial>
    </link>

    <gazebo reference="front_pitch_link">
        <kp>100000000000000.0</kp>
        <kd>100000000000000.0</kd>
        <mu1>0.5</mu1>
        <mu2>0.5</mu2>
        <material>Gazebo/Purple</material>
    </gazebo>

    <joint name="front_pitch_joint" type="continuous">
        <origin rpy="0 0 0" xyz="0 0 0" />
        <parent link="front_roll_link" />
        <child link="front_pitch_link" />
        <axis xyz="0 1 0" />
        <limit effort="1000.0" velocity="100.0" />
        <dynamics damping="0.0" friction="0.1"/>
    </joint>

    <!-- Caster Wheel Back -->
    <link name="back_yaw_link">
        <visual>
            <origin rpy="0 1.5707 1.5707" xyz="0 0 0"/>
            <geometry>
              <cylinder length="0.005" radius="0.04"/>
            </geometry>
            <material name="wooden"/>
        </visual>

        <collision>
            <origin rpy="0 1.5707 1.5707" xyz="0 0 0"/>
            <geometry>
                <cylinder length="0.005" radius="0.04"/>
            </geometry>
        </collision>

        <inertial>
            <origin rpy="0 1.5707 1.5707" xyz="0 0 0"/>
            <mass value="0.001"/>
            <inertia ixx="4.020833333333333e-07" ixy="0" ixz="0" iyy="4.020833333333333e-07" iyz="0" izz="8.000000000000001e-07"/>
        </inertial>
    </link>

    <joint name="back_yaw_joint" type="continuous">
        <origin rpy="0 0 0" xyz="0 0.15 -0.075"/>
        <parent link="chassis" />
        <child link="back_yaw_link" />
        <axis xyz="0 0 1" />
        <limit effort="1000.0" velocity="100.0" />
        <dynamics damping="0.0" friction="0.1"/>
    </joint>

    <gazebo reference="back_yaw_link">
        <material>Gazebo/Purple</material>
    </gazebo>

    <link name="back_roll_link">
        <visual>
            <origin rpy="0 1.5707 1.5707" xyz="0 0 0"/>
            <geometry>
                <cylinder length="0.005" radius="0.04"/>
            </geometry>
            <material name="wooden"/>
        </visual>

        <collision>
            <origin rpy="0 1.5707 1.5707" xyz="0 0 0"/>
            <geometry>
                <cylinder length="0.005" radius="0.04"/>
            </geometry>
        </collision>

        <inertial>
            <origin rpy="0 1.5707 1.5707" xyz="0 0 0"/>
            <mass value="0.001"/>
            <inertia ixx="4.020833333333333e-07" ixy="0" ixz="0" iyy="4.020833333333333e-07" iyz="0" izz="8.000000000000001e-07"/>
        </inertial>
    </link>

    <joint name="back_roll_joint" type="continuous">
        <origin rpy="0 0 0" xyz="0 0 0"/>
        <parent link="back_yaw_link"/>
        <child link="back_roll_link"/>
        <axis xyz="1 0 0" />
        <limit effort="1000.0" velocity="100.0" />
        <dynamics damping="0.0" friction="0.1"/>
    </joint>
        
    <gazebo reference="back_roll_link">
        <material>Gazebo/Purple</material>
    </gazebo>

    <link name="back_pitch_link">
        <visual>
            <origin rpy="0 1.5707 1.5707" xyz="0 0 0"/>
            <geometry>
                <sphere radius="0.04"/>
            </geometry>
            <material name="wooden"/>
        </visual>

        <collision>
            <origin rpy="0 1.5707 1.5707" xyz="0 0 0"/>
            <geometry>
                <sphere radius="0.04"/>
            </geometry>
        </collision>

        <inertial>
            <origin rpy="0 1.5707 1.5707" xyz="0 0 0"/>
            <mass value="0.001"/>
            <inertia ixx="6.4e-07" ixy="0" ixz="0" iyy="6.4e-07" iyz="0" izz="6.4e-07"/>
        </inertial>
    </link>

    <gazebo reference="back_pitch_link">
        <kp>100000000000000.0</kp>
        <kd>100000000000000.0</kd>
        <mu1>0.5</mu1>
        <mu2>0.5</mu2>
        <material>Gazebo/Purple</material>
    </gazebo>

    <joint name="back_pitch_joint" type="continuous">
        <origin rpy="0 0 0" xyz="0 0 0" />
        <parent link="back_roll_link" />
        <child link="back_pitch_link" />
        <axis xyz="0 1 0" />
        <limit effort="1000.0" velocity="100.0" />
        <dynamics damping="0.0" friction="0.1"/>
    </joint>

    <!-- L A S E R -->
    <link name="laser_frame">
        <visual>
            <geometry>
                <mesh filename="package://bot_description/meshes/sensors/rplidar.dae" scale="1.5 1.5 1.5"/>
            </geometry>
            <material name="black"/>
        </visual>
        <collision>
            <geometry>
                <cylinder radius="0.08" length="0.05"/>
            </geometry>
        </collision>
        <inertial>
            <origin xyz="0 0 0.075" rpy="0 0 0"/>
            <mass value="0.1"/>
            <inertia ixx="0.0001808333333333333" ixy="0" ixz="0" iyy="0.0001808333333333333" iyz="0" izz="0.00032"/>
        </inertial>
    </link>

    <joint name="laser_joint" type="fixed">
        <parent link="chassis"/>
        <child link="laser_frame"/>
        <origin xyz="0 0 0.08" rpy="0 0 1.57"/>
    </joint>

    <gazebo reference="laser_frame">
        <material>Gazebo/Black</material>
        <sensor name="laser" type="ray">
            <pose> 0 0 0 0 0 0 </pose>
            <visualize>false</visualize>
            <update_rate>30</update_rate>
            <ray>
                <scan>
                    <horizontal>
                        <samples>360</samples>
                        <min_angle>-3.14</min_angle>
                        <max_angle>3.14</max_angle>
                    </horizontal>
                </scan>
                <range>
                    <min>0.3</min>
                    <max>12</max>
                </range>
            </ray>
            <plugin name="laser_controller" filename="libgazebo_ros_ray_sensor.so">
                <ros>
                    <remapping>~/out:=scan</remapping>
                </ros>
                <output_type>sensor_msgs/LaserScan</output_type>
                <frame_name>laser_frame</frame_name>
            </plugin>
        </sensor>
    </gazebo>
    <ros2_control name="RealRobot" type="system">
        <hardware>
            <plugin>diffdrive_arduino/DiffDriveArduinoHardware</plugin>
            <param name="left_wheel_name">joint_left_wheel</param>
            <param name="right_wheel_name">joint_right_wheel</param>
            <param name="loop_rate">30.0</param>
            <param name="device">/dev/serial/by-path/pci-0000:00:14.0-usb-0:4:1.0</param>
            <param name="baud_rate">57600</param>
            <param name="timeout_ms">1000</param>
        </hardware>
        <joint name="joint_left_wheel">
            <command_interface name="velocity">
                <param name="min">-10</param>
                <param name="max">10</param>
            </command_interface>
            <state_interface name="position"/>
            <state_interface name="velocity"/>

        </joint>
        <joint name="joint_right_wheel">
            <command_interface name="velocity">
                <param name="min">-10</param>
                <param name="max">10</param>
            </command_interface>
            <state_interface name="position"/>
            <state_interface name="velocity"/>
        </joint>
    </ros2_control>
</robot>