<?xml version="1.0" ?>
<!-- =================================================================================== -->
<!-- |    This document was autogenerated by xacro from rover.xacro                    | -->
<!-- |    EDITING THIS FILE BY HAND IS NOT RECOMMENDED                                 | -->
<!-- =================================================================================== -->
<robot name="rover">
  <material name="silver">
    <color rgba="0.700 0.700 0.700 1.000"/>
  </material>
  <material name="wheel_black">
    <color rgba="0.325 0.337 0.353 0.5"/>
  </material>
  <material name="black">
    <color rgba="0.0 0.0 0.0"/>
  </material>
  <link name="base_link">
  </link>
  <link name="body">
    <inertial>
      <origin xyz="-0.003923470762597682 0.0 0.06851926704392347" rpy="0 0 0"/>
      <mass value="4.82539999999999"/>
      <inertia ixx = "0.027449999999999995" iyy = "0.08905" izz = "0.046079999999999996" ixy ="0" ixz ="0" iyz = "0"/>
     </inertial>
    <visual>
      <origin xyz="0 0 0" rpy="0 0 0"/>
      <geometry>
        <mesh filename="package://bot_description/meshes/body.stl" scale="0.001 0.001 0.001"/>
      </geometry>
      <material name="silver"/>
    </visual>
    <collision>
      <origin xyz="0 0 0" rpy="0 0 0"/>
      <geometry>
        <mesh filename="package://bot_description/meshes/body.stl" scale="0.001 0.001 0.001"/>
      </geometry>
    </collision>
  </link>
      
  <joint name="base_joint" type="fixed">
      <parent link="base_link"/>
      <child link="body"/>
      <origin xyz="0 0 0" rpy="0 0 0"/>
  </joint>

  <link name="base_footprint">
  </link>
    
  <joint name="footprint_joint" type="fixed">
      <parent link="base_link"/>
      <child link="base_footprint"/>
      <origin xyz="0 0 0" rpy="0 0 0"/>
  </joint>

  <link name="left_wheel1_1">
    <inertial>
      <origin xyz="0 0 0" rpy="1.57 0 0"/>
      <mass value="0.25"/>
      <inertia ixx ="0.0006583333333333334" iyy = "0.0006583333333333334" izz = "0.0012500000000000002" ixy = "0" ixz = "0" iyz = "0"/>
    </inertial>
    <visual>
      <origin xyz="0 0 0" rpy="1.57 0 0"/>
      <geometry>
        <cylinder length="0.04" radius="0.05"/>
      </geometry>
      <material name="silver"/>
    </visual>
    <collision>
      <origin xyz="0 0 0" rpy="1.57 0 0"/>
      <geometry>
        <cylinder length="0.04" radius="0.05"/>
      </geometry>
    </collision>
  </link>

  <link name="right_wheel1_1">
    <inertial>
      <origin xyz="0 0 0" rpy="1.57 0 0"/>
      <mass value="0.25"/>
      <inertia ixx ="0.0006583333333333334" iyy = "0.0006583333333333334" izz = "0.0012500000000000002" ixy = "0" ixz = "0" iyz = "0"/>
    </inertial>
    <visual>
      <origin xyz="0 0 0" rpy="1.57 0 0"/>
      <geometry>
        <cylinder length="0.04" radius="0.05"/>
      </geometry>
      <material name="silver"/>
    </visual>
    <collision>
      <origin xyz="0 0 0" rpy="1.57 0 0"/>
      <geometry>
        <cylinder length="0.04" radius="0.05"/>
      </geometry>
    </collision>
  </link>

  <link name="left_wheel2_1">
    <inertial>
      <origin xyz="0 0 0" rpy="1.57 0 0"/>
      <mass value="0.25"/>
      <inertia ixx ="0.0006583333333333334" iyy = "0.0006583333333333334" izz = "0.0012500000000000002" ixy = "0" ixz = "0" iyz = "0"/>
    </inertial>
    <visual>
      <origin xyz="0 0 0" rpy="1.57 0 0"/>
      <geometry>
        <cylinder length="0.04" radius="0.05"/>
      </geometry>
      <material name="silver"/>
    </visual>
    <collision>
      <origin xyz="0 0 0" rpy="1.57 0 0"/>
      <geometry>
        <cylinder length="0.04" radius="0.05"/>
      </geometry>
    </collision>
  </link>

  <link name="right_wheel2_1">
    <inertial>
      <origin xyz="0 0 0" rpy="1.57 0 0"/>
      <mass value="0.25"/>
      <inertia ixx ="0.0006583333333333334" iyy = "0.0006583333333333334" izz = "0.0012500000000000002" ixy = "0" ixz = "0" iyz = "0"/>
    </inertial>
    <visual>
      <origin xyz="0 0 0" rpy="1.57 0 0"/>
      <geometry>
        <cylinder length="0.04" radius="0.05"/>
      </geometry>
      <material name="silver"/>
    </visual>
    <collision>
      <origin xyz="0 0 0" rpy="1.57 0 0"/>
      <geometry>
        <cylinder length="0.04" radius="0.05"/>
      </geometry>
    </collision>
  </link>

  <joint name="revolute_1" type="continuous">
    <origin xyz="0.15 0.14 0.03" rpy="0 0 0"/>
    <parent link="body"/>
    <child link="left_wheel1_1"/>
    <axis xyz="0.0 1.0 0.0"/>
  </joint>

  <joint name="revolute_2" type="continuous">
    <origin xyz="0.15 -0.14 0.03" rpy="0 0 0"/>
    <parent link="body"/>
    <child link="right_wheel1_1"/>
    <axis xyz="0.0 -1.0 0.0"/>
  </joint>

  <joint name="revolute_3" type="continuous">
    <origin xyz="-0.15 0.14 0.03" rpy="0 0 0"/>
    <parent link="body"/>
    <child link="left_wheel2_1"/>
    <axis xyz="0.0 1.0 0.0"/>
  </joint>

  <joint name="revolute_4" type="continuous">
    <origin xyz="-0.15 -0.14 0.03" rpy="0 0 0"/>
    <parent link="body"/>
    <child link="right_wheel2_1"/>
    <axis xyz="0.0 -1.0 0.0"/>
  </joint>

  <gazebo reference="right_wheel1_1">
    <material>Gazebo/Black</material>
    <kp>100000000000000000000.0</kp>
    <kd>100000000000000000000.0</kd>
    <mu1>10</mu1>
    <mu2>10</mu2>
    <gravity>true</gravity>
  </gazebo>
  <gazebo reference="left_wheel1_1">
    <material>Gazebo/Black</material>
    <kp>100000000000000000000.0</kp>
    <kd>100000000000000000000.0</kd>
    <mu1>10</mu1>
    <mu2>10</mu2>
    <gravity>true</gravity>
  </gazebo>
  <gazebo reference="left_wheel2_1">
    <material>Gazebo/Black</material>
    <kp>100000000000000000000.0</kp>
    <kd>100000000000000000000.0</kd>
    <mu1>10</mu1>
    <mu2>10</mu2>
    <gravity>true</gravity>
  </gazebo>
  <gazebo reference="right_wheel2_1">
    <material>Gazebo/Black</material>
    <kp>100000000000000000000.0</kp>
    <kd>100000000000000000000.0</kd>
    <mu1>10</mu1>
    <mu2>10</mu2>
    <gravity>true</gravity>
  </gazebo>

  <link name="laser_frame">
    <visual>
      <geometry>
        <mesh filename="package://bot_description/meshes/sensors/rplidar.dae" scale="1.0 1.0 1.0"/>
      </geometry>
      <origin xyz="0 0 0" rpy="0 0 0"/>
      <material name="black"/>
    </visual>
    <collision>
      <origin xyz="0 0 0" rpy="0 0 0"/>
      <geometry>
        <cylinder radius="0.08" length="0.05"/>
      </geometry>
    </collision>
    <inertial>
      <origin xyz="0 0 0" rpy="0 0 0"/>
      <mass value="0.1"/>
      <inertia ixx="0.0001808333333333333" ixy="0" ixz="0" iyy="0.0001808333333333333" iyz="0" izz="0.00032"/>
    </inertial>
  </link>

  <joint name="laser_joint" type="fixed">
    <parent link="base_link"/>
    <child link="laser_frame"/>
    <origin xyz="0 0 0.15" rpy="0 0 1.57"/>
  </joint>

  <gazebo reference="laser_frame">
    <material>Gazebo/Black</material>
    <sensor name="laser" type="ray">
      <pose> 0 0 0 0 0 0 </pose>
      <visualize>true</visualize>
      <update_rate>30</update_rate>
      <ray>
        <scan>
          <horizontal>
            <samples>360</samples>
            <min_angle>-3.14</min_angle>
            <max_angle>3.14</max_angle>
          </horizontal>
        </scan>
        <range>
          <min>0.3</min>
          <max>12</max>
        </range>
      </ray>
      <plugin name="laser_controller" filename="libgazebo_ros_ray_sensor.so">
        <ros>
          <remapping>~/out:=scan</remapping>
        </ros>
        <output_type>sensor_msgs/LaserScan</output_type>
        <frame_name>laser_frame</frame_name>
      </plugin>
    </sensor>
  </gazebo>

  <gazebo>
    <plugin name="bot_joint_state" filename="libgazebo_ros_joint_state_publisher.so">
      <ros>
        <remapping>~/out:=joint_states</remapping>
      </ros>
      <update_rate>30</update_rate>

      <joint_name>revolute_1</joint_name>
      <joint_name>revolute_2</joint_name>
      <joint_name>revolute_3</joint_name>
      <joint_name>revolute_4</joint_name>
    </plugin>
  </gazebo>

  <gazebo>
    <plugin name="diff_drive_controller" filename="libgazebo_ros_diff_drive.so">
      <update_rate>100</update_rate>
      <num_wheel_pairs>2</num_wheel_pairs>

      <left_joint>revolute_1</left_joint>
      <right_joint>revolute_2</right_joint>
      <left_joint>revolute_3</left_joint>
      <right_joint>revolute_4</right_joint>

      <wheel_separation>0.24</wheel_separation>
      <wheel_diameter>0.10</wheel_diameter>

      <wheel_separation>0.24</wheel_separation>
      <wheel_diameter>0.10</wheel_diameter>

      <max_wheel_torque>15.0</max_wheel_torque>
      <max_wheel_acceleration>3.0</max_wheel_acceleration>
      <command_topic>cmd_vel</command_topic>
      <publish_odom>true</publish_odom>
      <publish_odom_tf>true</publish_odom_tf>
      <odometry_frame>odom</odometry_frame>
      <robot_base_frame>base_link</robot_base_frame>
      <publish_wheel_tf>true</publish_wheel_tf>
    </plugin>
  </gazebo>
</robot>
